python3 > -u -m torch.distributed.launch --nproc_per_node 8 --nnodes 1 --node_rank 0 --master_addr localhost --master_port 6002 .//finetune_bert_hf.py --model-version bert-base-cased --base-path ./ --dataset_name BoolQ --batch-size 16 --grad-accumulation 8 --lr 0.00001 --max-length 512 --train-iters 1400 --weight-decay 1e-2
/data/home/scv0540/miniconda3/envs/bmpretrain/lib/python3.7/site-packages/torch/distributed/launch.py:186: FutureWarning: The module torch.distributed.launch is deprecated
and will be removed in future. Use torchrun.
Note that --use_env is set by default in torchrun.
If your script expects `--local_rank` argument to be set, please
change it to read from `os.environ['LOCAL_RANK']` instead. See 
https://pytorch.org/docs/stable/distributed.html#launch-utility for 
further instructions

  FutureWarning,
WARNING:torch.distributed.run:
*****************************************
Setting OMP_NUM_THREADS environment variable for each process to be 1 in default, to avoid your system being overloaded, please further tune the variable for optimal performance in your application as needed. 
*****************************************
Traceback (most recent call last):
  File ".//finetune_bert_hf.py", line 7, in <module>
Traceback (most recent call last):
  File ".//finetune_bert_hf.py", line 7, in <module>
    from sklearn.metrics import accuracy_score, f1_score
ModuleNotFoundError: No module named 'sklearn'
    from sklearn.metrics import accuracy_score, f1_score
ModuleNotFoundError: No module named 'sklearn'
Traceback (most recent call last):
  File ".//finetune_bert_hf.py", line 7, in <module>
    from sklearn.metrics import accuracy_score, f1_score
ModuleNotFoundError: No module named 'sklearn'
Traceback (most recent call last):
  File ".//finetune_bert_hf.py", line 7, in <module>
Traceback (most recent call last):
  File ".//finetune_bert_hf.py", line 7, in <module>
    from sklearn.metrics import accuracy_score, f1_score
ModuleNotFoundError: No module named 'sklearn'
    from sklearn.metrics import accuracy_score, f1_score
ModuleNotFoundError: No module named 'sklearn'
Traceback (most recent call last):
  File ".//finetune_bert_hf.py", line 7, in <module>
    from sklearn.metrics import accuracy_score, f1_score
ModuleNotFoundError: No module named 'sklearn'
Traceback (most recent call last):
  File ".//finetune_bert_hf.py", line 7, in <module>
    from sklearn.metrics import accuracy_score, f1_score
ModuleNotFoundError: No module named 'sklearn'
Traceback (most recent call last):
  File ".//finetune_bert_hf.py", line 7, in <module>
    from sklearn.metrics import accuracy_score, f1_score
ModuleNotFoundError: No module named 'sklearn'
ERROR:torch.distributed.elastic.multiprocessing.api:failed (exitcode: 1) local_rank: 0 (pid: 44296) of binary: /data/home/scv0540/miniconda3/envs/bmpretrain/bin/python3
Traceback (most recent call last):
  File "/data/home/scv0540/miniconda3/envs/bmpretrain/lib/python3.7/runpy.py", line 193, in _run_module_as_main
    "__main__", mod_spec)
  File "/data/home/scv0540/miniconda3/envs/bmpretrain/lib/python3.7/runpy.py", line 85, in _run_code
    exec(code, run_globals)
  File "/data/home/scv0540/miniconda3/envs/bmpretrain/lib/python3.7/site-packages/torch/distributed/launch.py", line 193, in <module>
    main()
  File "/data/home/scv0540/miniconda3/envs/bmpretrain/lib/python3.7/site-packages/torch/distributed/launch.py", line 189, in main
    launch(args)
  File "/data/home/scv0540/miniconda3/envs/bmpretrain/lib/python3.7/site-packages/torch/distributed/launch.py", line 174, in launch
    run(args)
  File "/data/home/scv0540/miniconda3/envs/bmpretrain/lib/python3.7/site-packages/torch/distributed/run.py", line 713, in run
    )(*cmd_args)
  File "/data/home/scv0540/miniconda3/envs/bmpretrain/lib/python3.7/site-packages/torch/distributed/launcher/api.py", line 131, in __call__
    return launch_agent(self._config, self._entrypoint, list(args))
  File "/data/home/scv0540/miniconda3/envs/bmpretrain/lib/python3.7/site-packages/torch/distributed/launcher/api.py", line 261, in launch_agent
    failures=result.failures,
torch.distributed.elastic.multiprocessing.errors.ChildFailedError: 
============================================================
.//finetune_bert_hf.py FAILED
------------------------------------------------------------
Failures:
[1]:
  time      : 2022-03-20_19:59:31
  host      : g0016.para.ai
  rank      : 1 (local_rank: 1)
  exitcode  : 1 (pid: 44297)
  error_file: <N/A>
  traceback : To enable traceback see: https://pytorch.org/docs/stable/elastic/errors.html
[2]:
  time      : 2022-03-20_19:59:31
  host      : g0016.para.ai
  rank      : 2 (local_rank: 2)
  exitcode  : 1 (pid: 44298)
  error_file: <N/A>
  traceback : To enable traceback see: https://pytorch.org/docs/stable/elastic/errors.html
[3]:
  time      : 2022-03-20_19:59:31
  host      : g0016.para.ai
  rank      : 3 (local_rank: 3)
  exitcode  : 1 (pid: 44299)
  error_file: <N/A>
  traceback : To enable traceback see: https://pytorch.org/docs/stable/elastic/errors.html
[4]:
  time      : 2022-03-20_19:59:31
  host      : g0016.para.ai
  rank      : 4 (local_rank: 4)
  exitcode  : 1 (pid: 44300)
  error_file: <N/A>
  traceback : To enable traceback see: https://pytorch.org/docs/stable/elastic/errors.html
[5]:
  time      : 2022-03-20_19:59:31
  host      : g0016.para.ai
  rank      : 5 (local_rank: 5)
  exitcode  : 1 (pid: 44301)
  error_file: <N/A>
  traceback : To enable traceback see: https://pytorch.org/docs/stable/elastic/errors.html
[6]:
  time      : 2022-03-20_19:59:31
  host      : g0016.para.ai
  rank      : 6 (local_rank: 6)
  exitcode  : 1 (pid: 44302)
  error_file: <N/A>
  traceback : To enable traceback see: https://pytorch.org/docs/stable/elastic/errors.html
[7]:
  time      : 2022-03-20_19:59:31
  host      : g0016.para.ai
  rank      : 7 (local_rank: 7)
  exitcode  : 1 (pid: 44303)
  error_file: <N/A>
  traceback : To enable traceback see: https://pytorch.org/docs/stable/elastic/errors.html
------------------------------------------------------------
Root Cause (first observed failure):
[0]:
  time      : 2022-03-20_19:59:31
  host      : g0016.para.ai
  rank      : 0 (local_rank: 0)
  exitcode  : 1 (pid: 44296)
  error_file: <N/A>
  traceback : To enable traceback see: https://pytorch.org/docs/stable/elastic/errors.html
============================================================
